2022-06-08 16:16:34,971 (1599297/MainThread) litecli.main ERROR - sql: '.load ~/.config/zsh/.zsh_history.db\n;', error: OperationalError('Not connected to database.')
2022-06-08 16:16:34,977 (1599297/MainThread) litecli.main ERROR - traceback: 'Traceback (most recent call last):\n  File "/usr/lib/python3.10/site-packages/litecli/main.py", line 443, in one_iteration\n    for title, cur, headers, status in res:\n  File "/usr/lib/python3.10/site-packages/litecli/sqlexecute.py", line 115, in run\n    raise OperationalError("Not connected to database.")\nsqlite3.OperationalError: Not connected to database.\n'
2022-06-08 16:17:31,006 (1658011/MainThread) litecli.main ERROR - sql: 'select explain commands;', error: OperationalError('no such column: explain')
2022-06-08 16:17:31,014 (1658011/MainThread) litecli.main ERROR - traceback: 'Traceback (most recent call last):\n  File "/usr/lib/python3.10/site-packages/litecli/sqlexecute.py", line 122, in run\n    for result in special.execute(cur, sql):\n  File "/usr/lib/python3.10/site-packages/litecli/packages/special/main.py", line 109, in execute\n    raise CommandNotFound\nlitecli.packages.special.main.CommandNotFound\n\nDuring handling of the above exception, another exception occurred:\n\nTraceback (most recent call last):\n  File "/usr/lib/python3.10/site-packages/litecli/main.py", line 443, in one_iteration\n    for title, cur, headers, status in res:\n  File "/usr/lib/python3.10/site-packages/litecli/sqlexecute.py", line 126, in run\n    cur.execute(sql)\nsqlite3.OperationalError: no such column: explain\n'
2022-06-08 16:17:34,579 (1658011/MainThread) litecli.main ERROR - sql: 'explain commands;', error: OperationalError('near "commands": syntax error')
2022-06-08 16:17:34,580 (1658011/MainThread) litecli.main ERROR - traceback: 'Traceback (most recent call last):\n  File "/usr/lib/python3.10/site-packages/litecli/sqlexecute.py", line 122, in run\n    for result in special.execute(cur, sql):\n  File "/usr/lib/python3.10/site-packages/litecli/packages/special/main.py", line 109, in execute\n    raise CommandNotFound\nlitecli.packages.special.main.CommandNotFound\n\nDuring handling of the above exception, another exception occurred:\n\nTraceback (most recent call last):\n  File "/usr/lib/python3.10/site-packages/litecli/main.py", line 443, in one_iteration\n    for title, cur, headers, status in res:\n  File "/usr/lib/python3.10/site-packages/litecli/sqlexecute.py", line 126, in run\n    cur.execute(sql)\nsqlite3.OperationalError: near "commands": syntax error\n'
2022-06-08 16:20:46,317 (1658011/MainThread) litecli.main ERROR - sql: '.mode\nmoinmoin\n;', error: OperationalError('near ".": syntax error')
2022-06-08 16:20:46,318 (1658011/MainThread) litecli.main ERROR - traceback: 'Traceback (most recent call last):\n  File "/usr/lib/python3.10/site-packages/litecli/sqlexecute.py", line 122, in run\n    for result in special.execute(cur, sql):\n  File "/usr/lib/python3.10/site-packages/litecli/packages/special/main.py", line 109, in execute\n    raise CommandNotFound\nlitecli.packages.special.main.CommandNotFound\n\nDuring handling of the above exception, another exception occurred:\n\nTraceback (most recent call last):\n  File "/usr/lib/python3.10/site-packages/litecli/main.py", line 443, in one_iteration\n    for title, cur, headers, status in res:\n  File "/usr/lib/python3.10/site-packages/litecli/sqlexecute.py", line 126, in run\n    cur.execute(sql)\nsqlite3.OperationalError: near ".": syntax error\n'
2022-06-08 16:52:51,293 (1234745/MainThread) litecli.main ERROR - sql: '.read\n;', error: TypeError('.read accepts exactly one path')
2022-06-08 16:52:51,295 (1234745/MainThread) litecli.main ERROR - traceback: 'Traceback (most recent call last):\n  File "/usr/lib/python3.10/site-packages/litecli/main.py", line 443, in one_iteration\n    for title, cur, headers, status in res:\n  File "/usr/lib/python3.10/site-packages/litecli/sqlexecute.py", line 122, in run\n    for result in special.execute(cur, sql):\n  File "/usr/lib/python3.10/site-packages/litecli/packages/special/main.py", line 121, in execute\n    return special_cmd.handler(cur=cur, arg=arg, verbose=verbose)\n  File "/usr/lib/python3.10/site-packages/litecli/packages/special/dbcommands.py", line 215, in read_script\n    raise TypeError(".read accepts exactly one path")\nTypeError: .read accepts exactly one path\n'
2022-06-08 16:52:54,751 (1234745/MainThread) litecli.main ERROR - sql: '.help read;', error: OperationalError('near ".": syntax error')
2022-06-08 16:52:54,752 (1234745/MainThread) litecli.main ERROR - traceback: 'Traceback (most recent call last):\n  File "/usr/lib/python3.10/site-packages/litecli/sqlexecute.py", line 122, in run\n    for result in special.execute(cur, sql):\n  File "/usr/lib/python3.10/site-packages/litecli/packages/special/main.py", line 109, in execute\n    raise CommandNotFound\nlitecli.packages.special.main.CommandNotFound\n\nDuring handling of the above exception, another exception occurred:\n\nTraceback (most recent call last):\n  File "/usr/lib/python3.10/site-packages/litecli/main.py", line 443, in one_iteration\n    for title, cur, headers, status in res:\n  File "/usr/lib/python3.10/site-packages/litecli/sqlexecute.py", line 126, in run\n    cur.execute(sql)\nsqlite3.OperationalError: near ".": syntax error\n'
2022-06-08 16:52:59,778 (1234745/MainThread) litecli.main ERROR - sql: '.load help;', error: OperationalError('help.so: cannot open shared object file: No such file or directory')
2022-06-08 16:52:59,778 (1234745/MainThread) litecli.main ERROR - traceback: 'Traceback (most recent call last):\n  File "/usr/lib/python3.10/site-packages/litecli/main.py", line 443, in one_iteration\n    for title, cur, headers, status in res:\n  File "/usr/lib/python3.10/site-packages/litecli/sqlexecute.py", line 122, in run\n    for result in special.execute(cur, sql):\n  File "/usr/lib/python3.10/site-packages/litecli/packages/special/main.py", line 121, in execute\n    return special_cmd.handler(cur=cur, arg=arg, verbose=verbose)\n  File "/usr/lib/python3.10/site-packages/litecli/packages/special/dbcommands.py", line 170, in load_extension\n    conn.load_extension(path)\nsqlite3.OperationalError: help.so: cannot open shared object file: No such file or directory\n'
2022-06-08 16:53:11,037 (1234745/MainThread) litecli.main ERROR - sql: '.read help;', error: FileNotFoundError(2, 'No such file or directory')
2022-06-08 16:53:11,037 (1234745/MainThread) litecli.main ERROR - traceback: 'Traceback (most recent call last):\n  File "/usr/lib/python3.10/site-packages/litecli/main.py", line 443, in one_iteration\n    for title, cur, headers, status in res:\n  File "/usr/lib/python3.10/site-packages/litecli/sqlexecute.py", line 122, in run\n    for result in special.execute(cur, sql):\n  File "/usr/lib/python3.10/site-packages/litecli/packages/special/main.py", line 121, in execute\n    return special_cmd.handler(cur=cur, arg=arg, verbose=verbose)\n  File "/usr/lib/python3.10/site-packages/litecli/packages/special/dbcommands.py", line 217, in read_script\n    with open(path, "r") as f:\nFileNotFoundError: [Errno 2] No such file or directory: \'help\'\n'
2022-06-08 16:53:22,335 (1234745/MainThread) litecli.main ERROR - sql: '.help\n;', error: OperationalError('near ".": syntax error')
2022-06-08 16:53:22,335 (1234745/MainThread) litecli.main ERROR - traceback: 'Traceback (most recent call last):\n  File "/usr/lib/python3.10/site-packages/litecli/sqlexecute.py", line 122, in run\n    for result in special.execute(cur, sql):\n  File "/usr/lib/python3.10/site-packages/litecli/packages/special/main.py", line 109, in execute\n    raise CommandNotFound\nlitecli.packages.special.main.CommandNotFound\n\nDuring handling of the above exception, another exception occurred:\n\nTraceback (most recent call last):\n  File "/usr/lib/python3.10/site-packages/litecli/main.py", line 443, in one_iteration\n    for title, cur, headers, status in res:\n  File "/usr/lib/python3.10/site-packages/litecli/sqlexecute.py", line 126, in run\n    cur.execute(sql)\nsqlite3.OperationalError: near ".": syntax error\n'
2022-06-08 16:58:11,302 (1862206/MainThread) litecli.main ERROR - sql: 'select * from history join commands on commands.id = history.command_id order by command_id desc limit 20;', error: OperationalError('no such table: history')
2022-06-08 16:58:11,303 (1862206/MainThread) litecli.main ERROR - traceback: 'Traceback (most recent call last):\n  File "/usr/lib/python3.10/site-packages/litecli/sqlexecute.py", line 122, in run\n    for result in special.execute(cur, sql):\n  File "/usr/lib/python3.10/site-packages/litecli/packages/special/main.py", line 109, in execute\n    raise CommandNotFound\nlitecli.packages.special.main.CommandNotFound\n\nDuring handling of the above exception, another exception occurred:\n\nTraceback (most recent call last):\n  File "/usr/lib/python3.10/site-packages/litecli/main.py", line 443, in one_iteration\n    for title, cur, headers, status in res:\n  File "/usr/lib/python3.10/site-packages/litecli/sqlexecute.py", line 126, in run\n    cur.execute(sql)\nsqlite3.OperationalError: no such table: history\n'
2022-06-08 17:18:36,650 (2233208/MainThread) litecli.main ERROR - sql: 'select count(command_id) as cmdtimes, avg(history.duration) as duration, SUBSTr(commands.argv,1 20) as cmd from history join commands on commands.id = history.command_id GROUP BY commands.id order by command_id desc limit 40;', error: OperationalError('near "20": syntax error')
2022-06-08 17:18:36,667 (2233208/MainThread) litecli.main ERROR - traceback: 'Traceback (most recent call last):\n  File "/usr/lib/python3.10/site-packages/litecli/sqlexecute.py", line 122, in run\n    for result in special.execute(cur, sql):\n  File "/usr/lib/python3.10/site-packages/litecli/packages/special/main.py", line 109, in execute\n    raise CommandNotFound\nlitecli.packages.special.main.CommandNotFound\n\nDuring handling of the above exception, another exception occurred:\n\nTraceback (most recent call last):\n  File "/usr/lib/python3.10/site-packages/litecli/main.py", line 443, in one_iteration\n    for title, cur, headers, status in res:\n  File "/usr/lib/python3.10/site-packages/litecli/sqlexecute.py", line 126, in run\n    cur.execute(sql)\nsqlite3.OperationalError: near "20": syntax error\n'
2022-06-08 17:18:59,102 (2233208/MainThread) litecli.main ERROR - sql: 'select count(command_id) as cmdtimes, avg(history.duration) as duration, SUBSTr(commands.argv,1 20) as cmd from history join commands on commands.id = history.command_id GROUP BY commands.id order by command_id desc limit 40;', error: OperationalError('near "20": syntax error')
2022-06-08 17:18:59,103 (2233208/MainThread) litecli.main ERROR - traceback: 'Traceback (most recent call last):\n  File "/usr/lib/python3.10/site-packages/litecli/sqlexecute.py", line 122, in run\n    for result in special.execute(cur, sql):\n  File "/usr/lib/python3.10/site-packages/litecli/packages/special/main.py", line 109, in execute\n    raise CommandNotFound\nlitecli.packages.special.main.CommandNotFound\n\nDuring handling of the above exception, another exception occurred:\n\nTraceback (most recent call last):\n  File "/usr/lib/python3.10/site-packages/litecli/main.py", line 443, in one_iteration\n    for title, cur, headers, status in res:\n  File "/usr/lib/python3.10/site-packages/litecli/sqlexecute.py", line 126, in run\n    cur.execute(sql)\nsqlite3.OperationalError: near "20": syntax error\n'
2022-06-08 17:22:13,032 (2233208/MainThread) litecli.main ERROR - sql: 'select count(command_id) as cmdtimes, SUM(history.duration) as duration, concat(SUBSTr(commands.argv,1,10),substr(commands.argv,-10)) as cmd from history join commands on commands.id = history.command_id GROUP BY commands.id order by cmdtimes desc limit 40;', error: OperationalError('no such function: concat')
2022-06-08 17:22:13,032 (2233208/MainThread) litecli.main ERROR - traceback: 'Traceback (most recent call last):\n  File "/usr/lib/python3.10/site-packages/litecli/sqlexecute.py", line 122, in run\n    for result in special.execute(cur, sql):\n  File "/usr/lib/python3.10/site-packages/litecli/packages/special/main.py", line 109, in execute\n    raise CommandNotFound\nlitecli.packages.special.main.CommandNotFound\n\nDuring handling of the above exception, another exception occurred:\n\nTraceback (most recent call last):\n  File "/usr/lib/python3.10/site-packages/litecli/main.py", line 443, in one_iteration\n    for title, cur, headers, status in res:\n  File "/usr/lib/python3.10/site-packages/litecli/sqlexecute.py", line 126, in run\n    cur.execute(sql)\nsqlite3.OperationalError: no such function: concat\n'
2022-06-08 17:47:01,377 (2700328/MainThread) litecli.main ERROR - sql: '.show\n;', error: OperationalError('near ".": syntax error')
2022-06-08 17:47:01,381 (2700328/MainThread) litecli.main ERROR - traceback: 'Traceback (most recent call last):\n  File "/usr/lib/python3.10/site-packages/litecli/sqlexecute.py", line 122, in run\n    for result in special.execute(cur, sql):\n  File "/usr/lib/python3.10/site-packages/litecli/packages/special/main.py", line 109, in execute\n    raise CommandNotFound\nlitecli.packages.special.main.CommandNotFound\n\nDuring handling of the above exception, another exception occurred:\n\nTraceback (most recent call last):\n  File "/usr/lib/python3.10/site-packages/litecli/main.py", line 443, in one_iteration\n    for title, cur, headers, status in res:\n  File "/usr/lib/python3.10/site-packages/litecli/sqlexecute.py", line 126, in run\n    cur.execute(sql)\nsqlite3.OperationalError: near ".": syntax error\n'
